<?xml version="1.0" encoding="UTF-8"?>
<robot name="HAND_ARM">
  <joint name="FixedJoint" type="fixed">
    <origin xyz="0.107 0. 0. " rpy="-1.5707964 0.7853981 -1.5707963"/>
    <parent link="panda_instanceable_panda_link7"/>
    <child link="dg3f_l_dg_mount"/>
  </joint>
  <joint name="j_1_1" type="revolute">
    <origin xyz="0.0265 0. 0.06735" rpy="0. 0. 0."/>
    <parent link="dg3f_l_dg_mount"/>
    <child link="dg3f_l_1_1"/>
    <axis xyz="0. 0. 1."/>
    <limit lower="-1.5707999" upper="1.5707999" effort="7.6440001" velocity="3.1415927"/>
  </joint>
  <joint name="j_1_2" type="revolute">
    <origin xyz="-0.00115 0. 0.04235" rpy="0. 0. 0."/>
    <parent link="dg3f_l_1_1"/>
    <child link="dg3f_l_1_2"/>
    <axis xyz="1. 0. 0."/>
    <limit lower="-1.7627799" upper="1.7627799" effort="7.6440001" velocity="3.1415927"/>
  </joint>
  <joint name="j_1_3" type="revolute">
    <origin xyz="0.03258 0. 0.02022" rpy="-3.1415927 0. 0. "/>
    <parent link="dg3f_l_1_2"/>
    <child link="dg3f_l_1_3"/>
    <axis xyz="0. 1. 0."/>
    <limit lower="-0.15708" upper="2.5307298" effort="7.6440001" velocity="3.1415927"/>
  </joint>
  <joint name="j_1_4" type="revolute">
    <origin xyz="0.0434 0. -0. " rpy="0. 0. 0."/>
    <parent link="dg3f_l_1_3"/>
    <child link="dg3f_l_1_4"/>
    <axis xyz="0. 1. 0."/>
    <limit lower="-0.226893" upper="2.0245799" effort="7.6440001" velocity="3.1415927"/>
  </joint>
  <joint name="j_2_1" type="revolute">
    <origin xyz="-0.01334 0.023 0.06735" rpy="0. 0. 0."/>
    <parent link="dg3f_l_dg_mount"/>
    <child link="dg3f_l_2_1"/>
    <axis xyz="0. 0. 1."/>
    <limit lower="-1.5707999" upper="0.5235999" effort="7.6440001" velocity="3.1415927"/>
  </joint>
  <joint name="j_2_2" type="revolute">
    <origin xyz="0.00115 0. 0.04235" rpy="0. 0. -3.1415927"/>
    <parent link="dg3f_l_2_1"/>
    <child link="dg3f_l_2_2"/>
    <axis xyz="1. 0. 0."/>
    <limit lower="-1.7627799" upper="1.7627799" effort="7.6440001" velocity="3.1415927"/>
  </joint>
  <joint name="j_2_3" type="revolute">
    <origin xyz="0.03258 0. 0.02022" rpy="0. 0. 3.1415927"/>
    <parent link="dg3f_l_2_2"/>
    <child link="dg3f_l_2_3"/>
    <axis xyz="0. 1. 0."/>
    <limit lower="-0.15708" upper="2.5307298" effort="7.6440001" velocity="3.1415927"/>
  </joint>
  <joint name="j_2_4" type="revolute">
    <origin xyz="-0.0434 0. 0. " rpy="0. 0. 0."/>
    <parent link="dg3f_l_2_3"/>
    <child link="dg3f_l_2_4"/>
    <axis xyz="0. 1. 0."/>
    <limit lower="-0.226893" upper="2.0245799" effort="7.6440001" velocity="3.1415927"/>
  </joint>
  <joint name="j_3_1" type="revolute">
    <origin xyz="-0.01334 -0.023 0.06735" rpy="0. 0. 0."/>
    <parent link="dg3f_l_dg_mount"/>
    <child link="dg3f_l_3_1"/>
    <axis xyz="0. 0. 1."/>
    <limit lower="-0.5235999" upper="1.5707999" effort="7.6440001" velocity="3.1415927"/>
  </joint>
  <joint name="j_3_2" type="revolute">
    <origin xyz="0.00115 0. 0.04235" rpy="0. 0. -3.1415927"/>
    <parent link="dg3f_l_3_1"/>
    <child link="dg3f_l_3_2"/>
    <axis xyz="1. 0. 0."/>
    <limit lower="-1.7627799" upper="1.7627799" effort="7.6440001" velocity="3.1415927"/>
  </joint>
  <joint name="j_3_3" type="revolute">
    <origin xyz="0.03258 0. 0.02022" rpy="0. 0. 3.1415927"/>
    <parent link="dg3f_l_3_2"/>
    <child link="dg3f_l_3_3"/>
    <axis xyz="0. 1. 0."/>
    <limit lower="-0.15708" upper="2.5307298" effort="7.6440001" velocity="3.1415927"/>
  </joint>
  <joint name="j_3_4" type="revolute">
    <origin xyz="-0.0434 0. 0. " rpy="0. 0. 0."/>
    <parent link="dg3f_l_3_3"/>
    <child link="dg3f_l_3_4"/>
    <axis xyz="0. 1. 0."/>
    <limit lower="-0.226893" upper="2.0245799" effort="7.6440001" velocity="3.1415927"/>
  </joint>
  <joint name="panda_joint1" type="revolute">
    <origin xyz="0. 0. 0.333" rpy="0. -1.5707963 0. "/>
    <parent link="panda_instanceable_panda_link0"/>
    <child link="panda_instanceable_panda_link1"/>
    <axis xyz="1. 0. 0."/>
    <limit lower="-2.8973001" upper="2.8973001" effort="87." velocity="2.1749999"/>
  </joint>
  <joint name="panda_joint2" type="revolute">
    <origin xyz="0. 0. 0." rpy="0. 0. 1.5707964"/>
    <parent link="panda_instanceable_panda_link1"/>
    <child link="panda_instanceable_panda_link2"/>
    <axis xyz="1. 0. 0."/>
    <limit lower="-1.7628" upper="1.7628" effort="87." velocity="2.1749999"/>
  </joint>
  <joint name="panda_joint3" type="revolute">
    <origin xyz="0.0000002 -0.316 0. " rpy="-0. -0. -1.5707958"/>
    <parent link="panda_instanceable_panda_link2"/>
    <child link="panda_instanceable_panda_link3"/>
    <axis xyz="1. 0. 0."/>
    <limit lower="-2.8973001" upper="2.8973001" effort="87." velocity="2.1749999"/>
  </joint>
  <joint name="panda_joint4" type="revolute">
    <origin xyz="-0. -0.0000002 -0.0825 " rpy="-0. 0. -1.5707968"/>
    <parent link="panda_instanceable_panda_link3"/>
    <child link="panda_instanceable_panda_link4"/>
    <axis xyz="1. 0. 0."/>
    <limit lower="-3.0718" upper="-0.0698" effort="87." velocity="2.1749999"/>
  </joint>
  <joint name="panda_joint5" type="revolute">
    <origin xyz="0.0000001 0.3839999 0.0825 " rpy="0.0000001 0. 1.5707961"/>
    <parent link="panda_instanceable_panda_link4"/>
    <child link="panda_instanceable_panda_link5"/>
    <axis xyz="1. 0. 0."/>
    <limit lower="-2.8973001" upper="2.8973001" effort="12." velocity="2.6100004"/>
  </joint>
  <joint name="panda_joint6" type="revolute">
    <origin xyz="0.0000002 -0. -0. " rpy="0. -0.0000001 -1.5707961"/>
    <parent link="panda_instanceable_panda_link5"/>
    <child link="panda_instanceable_panda_link6"/>
    <axis xyz="1. 0. 0."/>
    <limit lower="-0.0175" upper="3.7525" effort="12." velocity="2.6100004"/>
  </joint>
  <joint name="panda_joint7" type="revolute">
    <origin xyz="-0. -0.0000001 -0.088 " rpy="0. 0. -1.5707964"/>
    <parent link="panda_instanceable_panda_link6"/>
    <child link="panda_instanceable_panda_link7"/>
    <axis xyz="1. 0. 0."/>
    <limit lower="-2.8973001" upper="2.8973001" effort="12." velocity="2.6100004"/>
  </joint>
  <joint name="rootJoint" type="fixed">
    <origin xyz="0. 0. 0." rpy="0. 0. 0."/>
    <parent link="HAND_ARM"/>
    <child link="panda_instanceable_panda_link0"/>
  </joint>
  <link name="HAND_ARM"/>
  <link name="dg3f_l_1_1">
    <inertial>
      <origin xyz="0.0003733 0. 0.027785 " rpy="0. 0. 0."/>
      <mass value="0.046"/>
      <inertia ixx="0.0000166" ixy="0." ixz="0.0000019" iyy="0.000019" iyz="0." izz="0.0000062"/>
    </inertial>
    <visual>
      <origin xyz="0. 0. 0." rpy="1.5707872 0. 0. "/>
      <geometry>
        <mesh filename="meshes/dg3f_l_1_1_visuals_l_1_1_mesh.obj" scale="1. 1. 1."/>
      </geometry>
    </visual>
    <visual>
      <origin xyz="0. 0. 0." rpy="0. 0. 0."/>
      <geometry>
        <mesh filename="meshes/l_1_1_c_mesh.obj" scale="1. 1. 1."/>
      </geometry>
    </visual>
  </link>
  <link name="dg3f_l_1_2">
    <inertial>
      <origin xyz="0.016772 -0.0000196 0.0097765" rpy="0. 0. 0."/>
      <mass value="0.027"/>
      <inertia ixx="0.0000037" ixy="0." ixz="-0.0000012" iyy="0.0000063" iyz="0." izz="0.0000068"/>
    </inertial>
    <visual>
      <origin xyz="0. 0. 0." rpy="1.5707872 0. 0. "/>
      <geometry>
        <mesh filename="meshes/dg3f_l_1_2_visuals_l_1_2_mesh.obj" scale="1. 1. 1."/>
      </geometry>
    </visual>
    <visual>
      <origin xyz="0. 0. 0." rpy="0. 0. 0."/>
      <geometry>
        <mesh filename="meshes/l_1_2_c_mesh.obj" scale="1. 1. 1."/>
      </geometry>
    </visual>
  </link>
  <link name="dg3f_l_1_3">
    <inertial>
      <origin xyz="0.01416 0.0000171 -0.0004553" rpy="0. 0. 0."/>
      <mass value="0.045"/>
      <inertia ixx="0.0000065" ixy="0." ixz="0.0000001" iyy="0.0000148" iyz="-0." izz="0.0000167"/>
    </inertial>
    <visual>
      <origin xyz="0. 0. -0." rpy="-1.5708054 0. 0. "/>
      <geometry>
        <mesh filename="meshes/dg3f_l_1_3_visuals_l_1_3_mesh.obj" scale="1. 1. 1."/>
      </geometry>
    </visual>
    <visual>
      <origin xyz="0. 0. -0." rpy="-3.1415927 0. 0. "/>
      <geometry>
        <mesh filename="meshes/l_1_3_c_mesh.obj" scale="1. 1. 1."/>
      </geometry>
    </visual>
  </link>
  <link name="dg3f_l_1_4">
    <inertial>
      <origin xyz="0.0206161 0.0000169 -0.0002839" rpy="0. 0. 0."/>
      <mass value="0.056"/>
      <inertia ixx="0.0000073" ixy="0." ixz="0.0000001" iyy="0.0000248" iyz="-0." izz="0.0000264"/>
    </inertial>
    <visual>
      <origin xyz="-0. 0. 0." rpy="-1.5708054 0. 0. "/>
      <geometry>
        <mesh filename="meshes/dg3f_l_1_4_visuals_l_1_4_mesh.obj" scale="1. 1. 1."/>
      </geometry>
    </visual>
    <visual>
      <origin xyz="0.0315 0. 0. " rpy="-1.5708054 0. 0. "/>
      <geometry>
        <mesh filename="meshes/dg3f_l_1_4_visuals_l_1_tip_mesh.obj" scale="1. 1. 1."/>
      </geometry>
    </visual>
    <visual>
      <origin xyz="-0. 0. 0." rpy="-3.1415927 0. 0. "/>
      <geometry>
        <mesh filename="meshes/l_1_4_c_mesh.obj" scale="1. 1. 1."/>
      </geometry>
    </visual>
    <visual>
      <origin xyz="0.0315 0. 0. " rpy="-3.1415927 0. 0. "/>
      <geometry>
        <mesh filename="meshes/l_1_tip_c_mesh.obj" scale="1. 1. 1."/>
      </geometry>
    </visual>
  </link>
  <link name="dg3f_l_2_1">
    <inertial>
      <origin xyz="-0.0003733 -0. 0.027785 " rpy="0. 0. 0."/>
      <mass value="0.046"/>
      <inertia ixx="0.0000166" ixy="0." ixz="-0.0000019" iyy="0.000019" iyz="-0." izz="0.0000062"/>
    </inertial>
    <visual>
      <origin xyz="0. 0. 0." rpy="1.5707872 0. 0. "/>
      <geometry>
        <mesh filename="meshes/dg3f_l_2_1_visuals_l_2_1_mesh.obj" scale="1. 1. 1."/>
      </geometry>
    </visual>
    <visual>
      <origin xyz="0. 0. 0." rpy="0. 0. 0."/>
      <geometry>
        <mesh filename="meshes/l_2_1_c_mesh.obj" scale="1. 1. 1."/>
      </geometry>
    </visual>
  </link>
  <link name="dg3f_l_2_2">
    <inertial>
      <origin xyz="-0.016772 0.0000196 0.0097765" rpy="0. 0. 0."/>
      <mass value="0.027"/>
      <inertia ixx="0.0000037" ixy="0." ixz="0.0000012" iyy="0.0000063" iyz="-0." izz="0.0000068"/>
    </inertial>
    <visual>
      <origin xyz="0. 0. 0." rpy="1.5707872 0. -3.1415927"/>
      <geometry>
        <mesh filename="meshes/dg3f_l_2_2_visuals_l_2_2_mesh.obj" scale="1. 1. 1."/>
      </geometry>
    </visual>
    <visual>
      <origin xyz="0. 0. 0." rpy="0. 0. -3.1415927"/>
      <geometry>
        <mesh filename="meshes/l_2_2_c_mesh.obj" scale="1. 1. 1."/>
      </geometry>
    </visual>
  </link>
  <link name="dg3f_l_2_3">
    <inertial>
      <origin xyz="-0.01416 -0.0000171 -0.0004553" rpy="0. 0. 0."/>
      <mass value="0.045"/>
      <inertia ixx="0.0000065" ixy="0." ixz="-0.0000001" iyy="0.0000148" iyz="0." izz="0.0000167"/>
    </inertial>
    <visual>
      <origin xyz="0. 0. 0." rpy="1.5707872 0. 0. "/>
      <geometry>
        <mesh filename="meshes/dg3f_l_2_3_visuals_l_2_3_mesh.obj" scale="1. 1. 1."/>
      </geometry>
    </visual>
    <visual>
      <origin xyz="0. 0. 0." rpy="0. 0. 0."/>
      <geometry>
        <mesh filename="meshes/l_2_3_c_mesh.obj" scale="1. 1. 1."/>
      </geometry>
    </visual>
  </link>
  <link name="dg3f_l_2_4">
    <inertial>
      <origin xyz="-0.0206162 -0.0000169 -0.0002839" rpy="0. 0. 0."/>
      <mass value="0.056"/>
      <inertia ixx="0.0000073" ixy="0." ixz="-0.0000001" iyy="0.0000248" iyz="0." izz="0.0000264"/>
    </inertial>
    <visual>
      <origin xyz="0. 0. 0." rpy="1.5707872 0. 0. "/>
      <geometry>
        <mesh filename="meshes/dg3f_l_2_4_visuals_l_2_4_mesh.obj" scale="1. 1. 1."/>
      </geometry>
    </visual>
    <visual>
      <origin xyz="-0.0315 0. 0. " rpy="1.5707872 0. 0. "/>
      <geometry>
        <mesh filename="meshes/dg3f_l_2_4_visuals_l_2_tip_mesh.obj" scale="1. 1. 1."/>
      </geometry>
    </visual>
    <visual>
      <origin xyz="0. 0. 0." rpy="0. 0. 0."/>
      <geometry>
        <mesh filename="meshes/l_2_4_c_mesh.obj" scale="1. 1. 1."/>
      </geometry>
    </visual>
    <visual>
      <origin xyz="-0.0315 0. 0. " rpy="0. 0. 0."/>
      <geometry>
        <mesh filename="meshes/l_2_tip_c_mesh.obj" scale="1. 1. 1."/>
      </geometry>
    </visual>
  </link>
  <link name="dg3f_l_3_1">
    <inertial>
      <origin xyz="0.0098 0.013827 0.015685" rpy="0. 0. 0."/>
      <mass value="0.046"/>
      <inertia ixx="0.000019" ixy="-0." ixz="0." iyy="0.0000166" iyz="-0.0000019" izz="0.0000062"/>
    </inertial>
    <visual>
      <origin xyz="0. 0. 0." rpy="1.5707872 0. 0. "/>
      <geometry>
        <mesh filename="meshes/dg3f_l_3_1_visuals_l_3_1_mesh.obj" scale="1. 1. 1."/>
      </geometry>
    </visual>
    <visual>
      <origin xyz="0. 0. 0." rpy="0. 0. 0."/>
      <geometry>
        <mesh filename="meshes/l_3_1_c_mesh.obj" scale="1. 1. 1."/>
      </geometry>
    </visual>
  </link>
  <link name="dg3f_l_3_2">
    <inertial>
      <origin xyz="0.015813 -0.010447 0.011455" rpy="0. 0. 0."/>
      <mass value="0.027"/>
      <inertia ixx="0.0000037" ixy="0.0000012" ixz="-0." iyy="0.0000068" iyz="0." izz="0.0000063"/>
    </inertial>
    <visual>
      <origin xyz="0. 0. 0." rpy="1.5707872 0. -3.1415927"/>
      <geometry>
        <mesh filename="meshes/dg3f_l_3_2_visuals_l_3_2_mesh.obj" scale="1. 1. 1."/>
      </geometry>
    </visual>
    <visual>
      <origin xyz="0. 0. 0." rpy="0. 0. -3.1415927"/>
      <geometry>
        <mesh filename="meshes/l_3_2_c_mesh.obj" scale="1. 1. 1."/>
      </geometry>
    </visual>
  </link>
  <link name="dg3f_l_3_3">
    <inertial>
      <origin xyz="0.00734 0.015833 -0.0004553" rpy="0. 0. 0."/>
      <mass value="0.045"/>
      <inertia ixx="0.0000065" ixy="0." ixz="-0.0000001" iyy="0.0000148" iyz="0." izz="0.0000167"/>
    </inertial>
    <visual>
      <origin xyz="0. 0. 0." rpy="1.5707872 0. 0. "/>
      <geometry>
        <mesh filename="meshes/dg3f_l_3_3_visuals_l_3_3_mesh.obj" scale="1. 1. 1."/>
      </geometry>
    </visual>
    <visual>
      <origin xyz="0. 0. 0." rpy="0. 0. 0."/>
      <geometry>
        <mesh filename="meshes/l_3_3_c_mesh.obj" scale="1. 1. 1."/>
      </geometry>
    </visual>
  </link>
  <link name="dg3f_l_3_4">
    <inertial>
      <origin xyz="0.0014294 0.0108041 0.014417 " rpy="0. 0. 0."/>
      <mass value="0.056"/>
      <inertia ixx="0.0000172" ixy="0.0000019" ixz="-0.00001" iyy="0.0000395" iyz="0.000001" izz="0.000031"/>
    </inertial>
    <visual>
      <origin xyz="0. 0. 0." rpy="1.5707872 0. 0. "/>
      <geometry>
        <mesh filename="meshes/dg3f_l_3_4_visuals_l_3_4_mesh.obj" scale="1. 1. 1."/>
      </geometry>
    </visual>
    <visual>
      <origin xyz="-0.0315 0. 0. " rpy="1.5707872 0. 0. "/>
      <geometry>
        <mesh filename="meshes/dg3f_l_3_4_visuals_l_3_tip_mesh.obj" scale="1. 1. 1."/>
      </geometry>
    </visual>
    <visual>
      <origin xyz="0. 0. 0." rpy="0. 0. 0."/>
      <geometry>
        <mesh filename="meshes/l_3_4_c_mesh.obj" scale="1. 1. 1."/>
      </geometry>
    </visual>
    <visual>
      <origin xyz="-0.0315 0. 0. " rpy="0. 0. 0."/>
      <geometry>
        <mesh filename="meshes/l_3_tip_c_mesh.obj" scale="1. 1. 1."/>
      </geometry>
    </visual>
  </link>
  <link name="dg3f_l_dg_mount">
    <inertial>
      <origin xyz="-0.0001446 0.0000002 0.041544 " rpy="0. 0. 0."/>
      <mass value="0.486"/>
      <inertia ixx="0.0006634" ixy="0." ixz="0.0000143" iyy="0.0006844" iyz="0." izz="0.0004112"/>
    </inertial>
    <visual>
      <origin xyz="0. 0. 0." rpy="1.5707872 0. 0. "/>
      <geometry>
        <mesh filename="meshes/dg3f_l_dg_mount_visuals_l_dg_mount_mesh.obj" scale="1. 1. 1."/>
      </geometry>
    </visual>
    <visual>
      <origin xyz="0. 0. 0.003" rpy="1.5707872 0. 0. "/>
      <geometry>
        <mesh filename="meshes/l_base_mesh.obj" scale="1. 1. 1."/>
      </geometry>
    </visual>
    <visual>
      <origin xyz="0. 0. 0." rpy="0. 0. 0."/>
      <geometry>
        <mesh filename="meshes/l_dg_mount_c_mesh.obj" scale="1. 1. 1."/>
      </geometry>
    </visual>
    <visual>
      <origin xyz="0. 0. 0.003" rpy="0. 0. 0."/>
      <geometry>
        <mesh filename="meshes/l_base_c_mesh.obj" scale="1. 1. 1."/>
      </geometry>
    </visual>
  </link>
  <link name="panda_instanceable_panda_link0">
    <visual>
      <origin xyz="0. 0. -0." rpy="0. 0. 0."/>
      <geometry>
        <mesh filename="meshes/panda_instanceable_panda_link0_visuals_panda_link0.obj" scale="1. 1. 1."/>
      </geometry>
    </visual>
    <collision>
      <origin xyz="0. 0. -0." rpy="0. 0. 0."/>
      <geometry>
        <mesh filename="meshes/panda_instanceable_panda_link0_collisions_collisions.obj" scale="1. 1. 1."/>
      </geometry>
    </collision>
  </link>
  <link name="panda_instanceable_panda_link1">
    <visual>
      <origin xyz="0. 0. 0." rpy="0. 1.5707963 0. "/>
      <geometry>
        <mesh filename="meshes/panda_instanceable_panda_link1_visuals_panda_link1.obj" scale="1. 1. 1."/>
      </geometry>
    </visual>
    <collision>
      <origin xyz="0. 0. 0." rpy="0. 1.5707963 0. "/>
      <geometry>
        <mesh filename="meshes/panda_instanceable_panda_link1_collisions_collisions.obj" scale="1. 1. 1."/>
      </geometry>
    </collision>
  </link>
  <link name="panda_instanceable_panda_link2">
    <visual>
      <origin xyz="-0. 0. -0." rpy="-0.0000005 1.5707964 0. "/>
      <geometry>
        <mesh filename="meshes/panda_instanceable_panda_link2_visuals_panda_link2.obj" scale="1. 1. 1."/>
      </geometry>
    </visual>
    <collision>
      <origin xyz="-0. 0. -0." rpy="-0.0000005 1.5707964 0. "/>
      <geometry>
        <mesh filename="meshes/panda_instanceable_panda_link2_collisions_collisions.obj" scale="1. 1. 1."/>
      </geometry>
    </collision>
  </link>
  <link name="panda_instanceable_panda_link3">
    <visual>
      <origin xyz="-0. -0.0000002 0. " rpy="0.0000005 1.5707963 0. "/>
      <geometry>
        <mesh filename="meshes/panda_instanceable_panda_link3_visuals_panda_link3.obj" scale="1. 1. 1."/>
      </geometry>
    </visual>
    <collision>
      <origin xyz="-0. -0.0000002 0. " rpy="0.0000005 1.5707963 0. "/>
      <geometry>
        <mesh filename="meshes/panda_instanceable_panda_link3_collisions_collisions.obj" scale="1. 1. 1."/>
      </geometry>
    </collision>
  </link>
  <link name="panda_instanceable_panda_link4">
    <visual>
      <origin xyz="-0. 0. 0." rpy="0.0000002 1.5707963 0. "/>
      <geometry>
        <mesh filename="meshes/panda_instanceable_panda_link4_visuals_panda_link4.obj" scale="1. 1. 1."/>
      </geometry>
    </visual>
    <collision>
      <origin xyz="-0. 0. 0." rpy="0.0000002 1.5707963 0. "/>
      <geometry>
        <mesh filename="meshes/panda_instanceable_panda_link4_collisions_collisions.obj" scale="1. 1. 1."/>
      </geometry>
    </collision>
  </link>
  <link name="panda_instanceable_panda_link5">
    <visual>
      <origin xyz="0.0000002 -0. -0. " rpy="-0.0000002 1.5707963 0. "/>
      <geometry>
        <mesh filename="meshes/panda_instanceable_panda_link5_visuals_panda_link5.obj" scale="1. 1. 1."/>
      </geometry>
    </visual>
    <collision>
      <origin xyz="0.0000002 -0. -0. " rpy="-0.0000002 1.5707963 0. "/>
      <geometry>
        <mesh filename="meshes/panda_instanceable_panda_link5_collisions_collisions.obj" scale="1. 1. 1."/>
      </geometry>
    </collision>
  </link>
  <link name="panda_instanceable_panda_link6">
    <visual>
      <origin xyz="-0. -0.0000001 -0. " rpy="0. 1.5707964 0. "/>
      <geometry>
        <mesh filename="meshes/panda_instanceable_panda_link6_visuals_panda_link6.obj" scale="1. 1. 1."/>
      </geometry>
    </visual>
    <collision>
      <origin xyz="-0. -0.0000001 -0. " rpy="0. 1.5707964 0. "/>
      <geometry>
        <mesh filename="meshes/panda_instanceable_panda_link6_collisions_collisions.obj" scale="1. 1. 1."/>
      </geometry>
    </collision>
  </link>
  <link name="panda_instanceable_panda_link7">
    <visual>
      <origin xyz="0. 0. 0." rpy="-0. 1.5707964 0. "/>
      <geometry>
        <mesh filename="meshes/panda_instanceable_panda_link7_visuals_panda_link7.obj" scale="1. 1. 1."/>
      </geometry>
    </visual>
    <collision>
      <origin xyz="0. 0. 0." rpy="-0. 1.5707964 0. "/>
      <geometry>
        <mesh filename="meshes/panda_instanceable_panda_link7_collisions_collisions.obj" scale="1. 1. 1."/>
      </geometry>
    </collision>
  </link>
</robot>
